<?xml version="1.0" ?>
<sdf version='1.7'>
  <model name='pongbotW'>

  <!-- <joint name="fixed to ground" type="fixed">
    <parent>world</parent>
    <child>BODY</child>
   </joint> -->

    <link name='BODY'>
      <inertial>
        <pose>-0.0105 -0.00051 0.00089 0 -0 0</pose>
        <mass>29.589</mass>
        <inertia>
          <ixx>0.23275</ixx>
          <ixy>-0.00319</ixy>
          <ixz>-0.00016</ixz>
          <iyy>1.3481</iyy>
          <iyz>-0.00019</iyz>
          <izz>1.4819</izz>
        </inertia>
      </inertial>
      <!-- <collision name='BODY_collision'>
        <pose>0 0 0 0 -0 0</pose>
        <geometry>
          <box>
            <size>0.5 0.3 0.12</size>
          </box>
        </geometry>
      </collision> -->
      <visual name='BODY_visual'>
        <pose>0 0 0 0 -0 0</pose>
        <geometry>
          <mesh>
            <scale>1 1 1</scale>
            <uri>model://PONGBOT_W/meshes/BODY.STL</uri>
          </mesh>
        </geometry>
          <material>
          <ambient>0 0 0 1</ambient>
          <diffuse>1 1 1 1</diffuse>
          <emissive>0 0 0 0</emissive>
          <specular>0 0 0 0</specular>
        </material>
      </visual>
      <!-- <visual name='BODY_visual'>
        <pose>0 0 0 0 -0 0</pose>
        <geometry>
          <box>
            <size>0.5 0.3 0.12</size>
          </box>
        </geometry>
      </visual> -->
      <sensor name='IMU' type='imu'>
        <pose relative_to='BODY'>0 0 0 0 -0 0</pose>
        <imu>
          <angular_velocity>
            <x>
              <noise type='none'></noise>
            </x>
            <y>
              <noise type='none'></noise>
            </y>
            <z>
              <noise type='none'></noise>
            </z>
          </angular_velocity>
          <linear_acceleration>
            <x>
              <noise type='none'></noise>
            </x>
            <y>
              <noise type="none"></noise>
            </y>
            <z>
              <noise type='none'></noise>
            </z>
          </linear_acceleration>
        </imu>
        <always_on>1</always_on>
        <update_rate>1000</update_rate>
        <visualize>true</visualize>
      </sensor>
    </link>
    <joint name='FL_HR_JOINT' type='revolute'>
      <pose relative_to='BODY'>0.31804 0.1138 0 0 -0 0</pose>
      <parent>BODY</parent>
      <child>FL_HIP</child>
      <axis>
        <xyz>1 0 0</xyz>
        <limit>
          <!-- <lower>-1e+16</lower>
          <upper>1e+16</upper> -->
          <lower>-0.6283</lower>
          <upper>0.6283</upper>
          <effort>76.5</effort>
          <velocity>14.5</velocity>
        </limit>
        <dynamics>
          <spring_reference>0</spring_reference>
          <spring_stiffness>0</spring_stiffness>
        </dynamics>
      </axis>
    </joint>
    <link name='FL_HIP'>
      <pose relative_to='FL_HR_JOINT'>0 0 0 0 -0 0</pose>
      <inertial>
        <pose>0.00261 -0.00524 0.00014 0 -0 0</pose>
        <mass>1.5871</mass>
        <inertia>
          <ixx>0.00134</ixx>
          <ixy>0</ixy>
          <ixz>1e-05</ixz>
          <iyy>0.00194</iyy>
          <iyz>-2e-05</iyz>
          <izz>0.00158</izz>
        </inertia>
      </inertial>
      <!-- <collision name='FL_HIP_collision'>
        <pose>0 0 0 0 -0 0</pose>
        <geometry>
          <box>
            <size>0.1 0.08 0.1</size>
          </box>
        </geometry>
      </collision> -->
      <visual name='FL_HIP_visual'>
        <pose>0 0 0 0 -0 0</pose>
        <geometry>
          <mesh>
            <scale>1 1 1</scale>
            <uri>model://PONGBOT_W/meshes/FL_HIP.STL</uri>
          </mesh>
        </geometry>
        <material>
          <ambient>244 67 54 1</ambient>
          <diffuse>1 1 1 1</diffuse>
          <emissive>0 0 0 1</emissive>
          <specular>0 0 0 0</specular>
        </material>
      </visual>
      <!-- <visual name='FL_HIP_visual'>
        <pose>0 0 0 0 -0 0</pose>
        <geometry>
          <box>
            <size>0.1 0.08 0.1</size>
          </box>
        </geometry>
      </visual> -->
    </link>
    <joint name='FL_HP_JOINT' type='revolute'>
      <pose relative_to='FL_HIP'>0 0.105 0 0 -0 0</pose>
      <parent>FL_HIP</parent>
      <child>FL_THIGH</child>
      <axis>
        <xyz>0 1 0</xyz>
        <limit>
          <!-- <lower>-1e+16</lower>
          <upper>1e+16</upper> -->
          <lower>-0.9075</lower>
          <upper>3.0194</upper>
          <effort>150</effort>
          <velocity>8.2</velocity>
        </limit>
        <dynamics>
          <spring_reference>0</spring_reference>
          <spring_stiffness>0</spring_stiffness>
          <!-- <damping>0.25</damping>
          <friction>0.02</friction> -->
        </dynamics>
      </axis>
    </joint>
    <link name='FL_THIGH'>
      <pose relative_to='FL_HP_JOINT'>0 0 0 0 -0 0</pose>
      <inertial>
        <pose>-7e-05 -0.00772 -0.03599 0 -0 0</pose>
        <mass>3.32</mass>
        <inertia>
          <ixx>0.027</ixx>
          <ixy>-5e-05</ixy>
          <ixz>-3e-05</ixz>
          <iyy>0.02726</iyy>
          <iyz>-0.00086</iyz>
          <izz>0.00394</izz>
        </inertia>
      </inertial>
      <!-- <collision name='FL_THIGH_collision'>
        <pose>0 0 -0.15 0 -0 0</pose>
        <geometry>
          <box>
            <size>0.08 0.05 0.3</size>
          </box>
        </geometry>
      </collision> -->
      <visual name='FL_THIGH_visual'>
        <pose>0 0 0 0 -0 0</pose>
        <geometry>
          <mesh>
            <scale>1 1 1</scale>
            <uri>model://PONGBOT_W/meshes/FL_THIGH.STL</uri>
          </mesh>
        </geometry>
        <material>
          <ambient>244 67 54 1</ambient>
          <diffuse>1 1 1 1</diffuse>
          <emissive>0 0 0 1</emissive>
          <specular>0 0 0 0</specular>
        </material>
      </visual>
    </link>
    <joint name='FL_KN_JOINT' type='revolute'>
      <pose relative_to='FL_THIGH'>0 0 -0.305 0 -0 0</pose>
      <parent>FL_THIGH</parent>
      <child>FL_CALF</child>
      <axis>
        <xyz>0 1 0</xyz>
        <limit>
          <!-- <lower>-1e+16</lower>
          <upper>1e+16</upper> -->
          <lower>-2.4958</lower>
          <upper>-0.6457</upper>
          <effort>268.5</effort>
          <velocity>4.82</velocity>
        </limit>
        <dynamics>
          <spring_reference>0</spring_reference>
          <spring_stiffness>0</spring_stiffness>
          <!-- <damping>0.25</damping>
          <friction>0.02</friction> -->
        </dynamics>
      </axis>
    </joint>
    <link name='FL_CALF'>
      <pose relative_to='FL_KN_JOINT'>0 0 0 0 -0 0</pose>
      <inertial>
        <pose>0.00554 -0.00354 -0.22683 0 -0 0</pose>
        <mass>1.4843</mass>
        <inertia>
          <ixx>0.02812</ixx>
          <ixy>4E-05</ixy>
          <ixz>-0.00038</ixz>
          <iyy>0.02856</iyy>
          <iyz>0.00133</iyz>
          <izz>0.00135</izz>
        </inertia>
      </inertial>
      <!-- <collision name='FL_CALF_collision'>
        <pose>0 0 0 0 -0 0</pose>
        <geometry>
          <mesh>
            <scale>1 1 1</scale>
            <uri>model://PONGBOT_W/meshes/FL_CALF.STL</uri>
          </mesh>
        </geometry>
      </collision> -->
      <!-- <collision name='FL_CALF_fixed_joint_lump__FL_WHEEL_collision_1'>
        <pose>0 0.0405 -0.3292 1.5708 -0 0</pose>
        <geometry>
          <cylinder>
            <length>0.04</length>
            <radius>0.108</radius>
          </cylinder>
        </geometry>
      </collision> -->
      <visual name='FL_CALF_visual'>
        <pose>0 0 0 0 -0 0</pose>
        <geometry>
          <mesh>
            <scale>1 1 1</scale>
            <uri>model://PONGBOT_W/meshes/FL_CALF.STL</uri>
          </mesh>
        </geometry>
        <material>
          <ambient>0 0 0 1</ambient>
          <diffuse>1 1 1 1</diffuse>
          <emissive>0 0 0 1</emissive>
          <specular>0 0 0 0</specular>
        </material>
      </visual>
      <!-- <visual name='FL_CALF_fixed_joint_lump__FL_WHEEL_visual_1'>
        <pose>0 0.0405 -0.3292 0 -0 0</pose>
        <geometry>
          <mesh>
            <scale>1 1 1</scale>
            <uri>model://PONGBOT_W/meshes/FL_WHEEL.STL</uri>
          </mesh>
        </geometry>
      </visual> -->
    </link>
    <joint name='FL_WHEEL_JOINT' type='fixed'>
      <pose relative_to='FL_CALF'>0 0.0405 -0.3292 0 -0 0</pose>
      <parent>FL_CALF</parent>
      <child>FL_WHEEL</child>
      <!-- <axis>
        <xyz>0 1 0</xyz>
        <limit>
          <lower>-1e+16</lower>
          <upper>1e+16</upper>
        </limit>
        <dynamics>
          <spring_reference>0</spring_reference>
          <spring_stiffness>0</spring_stiffness>
          <damping>0.25</damping>
          <friction>0.02</friction>
        </dynamics>
      </axis> -->
    </joint>
    <link name='FL_WHEEL'>
      <pose relative_to='FL_WHEEL_JOINT'>0 0 0 0 -0 0</pose>
      <inertial>
        <pose>0 -0.00076 0 0 -0 0</pose>
        <mass>1.1204</mass>
        <inertia>
          <ixx>0.00401</ixx>
          <ixy>0</ixy>
          <ixz>0</ixz>
          <iyy>0.00769</iyy>
          <iyz>0</iyz>
          <izz>0.00401</izz>
        </inertia>
      </inertial>
      <collision name='FL_WHEEL_collision'>
        <pose>0 0 0 1.5708 -0 0</pose>
        <geometry>
          <!--mesh>
            <scale>1 1 1</scale>
            <uri>model://PONGBOT_W/meshes/FL_WHEEL.STL</uri>
          </mesh-->
          <cylinder>
            <radius>0.108</radius>
            <length>0.04</length>  
            <!-- <cylinder> -->
            <!-- <radius>0.109</radius> -->
            <!-- <length>0.048</length>  -->
          </cylinder>
        </geometry>
        <surface>
          <bounce>
            <restitution_coefficient> 0 </restitution_coefficient>
          </bounce>
          <friction>
            <ode>
              <!-- <mu>  100  </mu>
              <mu2> 10  </mu2> -->
              <mu>  1.5  </mu>
              <mu2> 1.5  </mu2>
              <slip1> 0.0  </slip1>
              <slip2> 0.0  </slip2>
            </ode>
          </friction>
          <contact>
            <ode>
      	      <!-- <kp>10000000</kp>
              <kd>10000</kd> -->
              <kp>12500000</kp>
              <kd>3125</kd>
              <!--<max_vel>0.1</max_vel>
              <min_depth>0.0001</min_depth> -->
            </ode>
          </contact>
        </surface>      
      </collision>
      <visual name='FL_WHEEL_visual'>
        <pose>0 0 0 0 -0 0</pose>
        <geometry>
          <mesh>
            <scale>1 1 1</scale>
            <uri>model://PONGBOT_W/meshes/FL_WHEEL.STL</uri>
          </mesh>
        </geometry>
        <material>
          <ambient>0 0 0 1</ambient>
          <diffuse>1 1 1 1</diffuse>
          <emissive>0 0 0 1</emissive>
          <specular>0 0 0 0</specular>
        </material>
      </visual>
    </link>


    <joint name='FR_HR_JOINT' type='revolute'>
      <pose relative_to='BODY'>0.31804 -0.1138 0 0 -0 0</pose>
      <parent>BODY</parent>
      <child>FR_HIP</child>
      <axis>
        <xyz>1 0 0</xyz>
        <limit>
          <!-- <lower>-1e+16</lower>
          <upper>1e+16</upper> -->
          <lower>-0.6283</lower>
          <upper>0.6283</upper>
          <effort>76.5</effort>
          <velocity>14.5</velocity>
        </limit>
        <dynamics>
          <spring_reference>0</spring_reference>
          <spring_stiffness>0</spring_stiffness>
        </dynamics>
      </axis>
    </joint>
    <link name='FR_HIP'>
      <pose relative_to='FR_HR_JOINT'>0 0 0 0 -0 0</pose>
      <inertial>
        <pose>0.0027 0.00524 0.00022 0 -0 0</pose>
        <mass>1.5871</mass>
        <inertia>
          <ixx>0.00134</ixx>
          <ixy>-1e-05</ixy>
          <ixz>-1e-05</ixz>
          <iyy>0.00194</iyy>
          <iyz>-4e-05</iyz>
          <izz>0.00158</izz>
        </inertia>
      </inertial>
      <!-- <collision name='FR_HIP_collision'>
        <pose>0 0 0 0 -0 0</pose>
        <geometry>
          <box>
            <size>0.1 0.08 0.1</size>
          </box>
        </geometry>
      </collision> -->
      <visual name='FR_HIP_visual'>
        <pose>0 0 0 0 -0 0</pose>
        <geometry>
          <mesh>
            <scale>1 1 1</scale>
            <uri>model://PONGBOT_W/meshes/FR_HIP.STL</uri>
          </mesh>
        </geometry>
        <material>
          <ambient>244 67 54 1</ambient>
          <diffuse>1 1 1 1</diffuse>
          <emissive>0 0 0 1</emissive>
          <specular>0 0 0 0</specular>
        </material>
      </visual>
      <!-- <visual name='FR_HIP_visual'>
        <pose>0 0 0 0 -0 0</pose>
        <geometry>
          <box>
            <size>0.1 0.08 0.1</size>
          </box>
        </geometry>
      </visual> -->
    </link>
    <joint name='FR_HP_JOINT' type='revolute'>
      <pose relative_to='FR_HIP'>0 -0.105 0 0 -0 0</pose>
      <parent>FR_HIP</parent>
      <child>FR_THIGH</child>
      <axis>
        <xyz>0 1 0</xyz>
        <limit>
          <!-- <lower>-1e+16</lower>
          <upper>1e+16</upper> -->
          <lower>-0.9075</lower>
          <upper>3.0194</upper>
          <effort>150</effort>
          <velocity>8.2</velocity>
        </limit>
        <dynamics>
          <spring_reference>0</spring_reference>
          <spring_stiffness>0</spring_stiffness>
          <!-- <damping>0.25</damping>
          <friction>0.02</friction> -->
        </dynamics>
      </axis>
    </joint>
    <link name='FR_THIGH'>
      <pose relative_to='FR_HP_JOINT'>0 0 0 0 -0 0</pose>
      <inertial>
        <pose>7e-05 0.00772 -0.03599 0 -0 0</pose>
        <mass>3.32</mass>
        <inertia>
          <ixx>0.027</ixx>
          <ixy>-5e-05</ixy>
          <ixz>3e-05</ixz>
          <iyy>0.02726</iyy>
          <iyz>0.00086</iyz>
          <izz>0.00394</izz>
        </inertia>
      </inertial>
      <!-- <collision name='FR_THIGH_collision'>
        <pose>0 0 -0.15 0 -0 0</pose>
        <geometry>
          <box>
            <size>0.08 0.05 0.3</size>
          </box>
        </geometry>
      </collision> -->
      <visual name='FR_THIGH_visual'>
        <pose>0 0 0 0 -0 0</pose>
        <geometry>
          <mesh>
            <scale>1 1 1</scale>
            <uri>model://PONGBOT_W/meshes/FR_THIGH.STL</uri>
          </mesh>
        </geometry>
        <material>
          <ambient>244 67 54 1</ambient>
          <diffuse>1 1 1 1</diffuse>
          <emissive>0 0 0 1</emissive>
          <specular>0 0 0 0</specular>
        </material>
      </visual>
    </link>
    <joint name='FR_KN_JOINT' type='revolute'>
      <pose relative_to='FR_THIGH'>0 0 -0.305 0 -0 0</pose>
      <parent>FR_THIGH</parent>
      <child>FR_CALF</child>
      <axis>
        <xyz>0 1 0</xyz>
        <limit>
          <!-- <lower>-1e+16</lower>
          <upper>1e+16</upper> -->
          <lower>-2.4958</lower>
          <upper>-0.6457</upper>
          <effort>268.5</effort>
          <velocity>4.82</velocity>
        </limit>
        <dynamics>
          <spring_reference>0</spring_reference>
          <spring_stiffness>0</spring_stiffness>
          <!-- <damping>0.25</damping>
          <friction>0.02</friction> -->
        </dynamics>
      </axis>
    </joint>
    <link name='FR_CALF'>
      <pose relative_to='FR_KN_JOINT'>0 0 0 0 -0 0</pose>
      <inertial>
        <pose>0.00555 0.00354 -0.22683 0 -0 0</pose>
        <mass>1.4843</mass>
        <inertia>
          <ixx>0.02812</ixx>
          <ixy>-4E-05</ixy>
          <ixz>-0.00038</ixz>
          <iyy>0.02856</iyy>
          <iyz>-0.00133</iyz>
          <izz>0.00135</izz>
        </inertia>
      </inertial>
      <!-- <collision name='FR_CALF_collision'>
        <pose>0 0 0 0 -0 0</pose>
        <geometry>
          <mesh>
            <scale>1 1 1</scale>
            <uri>model://PONGBOT_W/meshes/FR_CALF.STL</uri>
          </mesh>
        </geometry>
      </collision> -->
      <!-- <collision name='FR_CALF_fixed_joint_lump__FR_WHEEL_collision_1'>
        <pose>0 -0.0405 -0.3292 1.5708 -0 0</pose>
        <geometry>
          <cylinder>
            <length>0.04</length>
            <radius>0.108</radius>
          </cylinder>
        </geometry>
      </collision> -->
      <visual name='FR_CALF_visual'>
        <pose>0 0 0 0 -0 0</pose>
        <geometry>
          <mesh>
            <scale>1 1 1</scale>
            <uri>model://PONGBOT_W/meshes/FR_CALF.STL</uri>
          </mesh>
        </geometry>
        <material>
          <ambient>0 0 0 1</ambient>
          <diffuse>1 1 1 1</diffuse>
          <emissive>0 0 0 1</emissive>
          <specular>0 0 0 0</specular>
        </material>
      </visual>
      <!-- <visual name='FR_CALF_fixed_joint_lump__FR_WHEEL_visual_1'>
        <pose>0 -0.0405 -0.3292 0 -0 0</pose>
        <geometry>
          <mesh>
            <scale>1 1 1</scale>
            <uri>model://PONGBOT_W/meshes/FR_WHEEL.STL</uri>
          </mesh>
        </geometry>
      </visual> -->
    </link>
    <joint name='FR_WHEEL_JOINT' type='fixed'>
      <pose relative_to='FR_CALF'>0 -0.0405 -0.3292 0 -0 0</pose>
      <parent>FR_CALF</parent>
      <child>FR_WHEEL</child>
        <!-- <axis>
        <xyz>0 1 0</xyz>
        <limit>
          <lower>-1e+16</lower>
          <upper>1e+16</upper>
        </limit>
        <dynamics>
          <spring_reference>0</spring_reference>
          <spring_stiffness>0</spring_stiffness>
            <damping>0.25</damping>
            <friction>0.02</friction>
        </dynamics>
        </axis> -->
    </joint>
    <link name='FR_WHEEL'>
      <pose relative_to='FR_WHEEL_JOINT'>0 0 0 0 -0 0</pose>
      <inertial>
        <pose>0 0.00076 0 0 -0 0</pose>
        <mass>1.1204</mass>
        <inertia>
          <ixx>0.00401</ixx>
          <ixy>0</ixy>
          <ixz>0</ixz>
          <iyy>0.00769</iyy>
          <iyz>0</iyz>
          <izz>0.00401</izz>
        </inertia>
      </inertial>
      <collision name='FR_WHEEL_collision'>
        <pose>0 0 0 1.5708 -0 0</pose>
        <geometry>
          <!--mesh>
            <scale>1 1 1</scale>
            <uri>model://PONGBOT_W/meshes/FR_WHEEL.STL</uri>
          </mesh-->
          <cylinder>
            <radius>0.108</radius>
            <length>0.04</length>  
          </cylinder>
        </geometry>
                <surface>
          <bounce>
            <restitution_coefficient> 0 </restitution_coefficient>
          </bounce>
          <friction>
            <ode>
              <!-- <mu>  100  </mu>
              <mu2> 10  </mu2> -->
              <mu>  1.5  </mu>
              <mu2> 1.5  </mu2>
              <slip1> 0.0  </slip1>
              <slip2> 0.0  </slip2>
            </ode>
          </friction>
          <contact>
            <ode>
      	      <!-- <kp>10000000</kp>
              <kd>10000</kd> -->
              <kp>12500000</kp>
              <kd>3125</kd>
              <!--<max_vel>0.1</max_vel>
              <min_depth>0.0001</min_depth> -->
            </ode>
          </contact>
        </surface>
      </collision>
      <visual name='FR_WHEEL_visual'>
        <pose>0 0 0 0 -0 0</pose>
        <geometry>
          <mesh>
            <scale>1 1 1</scale>
            <uri>model://PONGBOT_W/meshes/FR_WHEEL.STL</uri>
          </mesh>
        </geometry>
        <material>
          <ambient>0 0 0 1</ambient>
          <diffuse>1 1 1 1</diffuse>
          <emissive>0 0 0 1</emissive>
          <specular>0 0 0 0</specular>
        </material>
      </visual>
    </link>

    <joint name='RL_HR_JOINT' type='revolute'>
      <pose relative_to='BODY'>-0.31804 0.1138 0 0 -0 0</pose>
      <parent>BODY</parent>
      <child>RL_HIP</child>
      <axis>
        <xyz>1 0 0</xyz>
        <limit>
          <!-- <lower>-1e+16</lower>
          <upper>1e+16</upper> -->
          <lower>-0.6283</lower>
          <upper>0.6283</upper>
          <effort>76.5</effort>
          <velocity>14.5</velocity>
        </limit>
        <dynamics>
          <spring_reference>0</spring_reference>
          <spring_stiffness>0</spring_stiffness>
          <!-- <damping>0.25</damping>
          <friction>0.02</friction> -->
        </dynamics>
      </axis>
    </joint>
    <link name='RL_HIP'>
      <pose relative_to='RL_HR_JOINT'>0 0 0 0 -0 0</pose>
      <inertial>
        <pose>-0.0029 -0.00524 -0.00073 0 -0 0</pose>
        <mass>1.5871</mass>
        <inertia>
          <ixx>0.00134</ixx>
          <ixy>-1e-05</ixy>
          <ixz>1e-05</ixz>
          <iyy>0.00194</iyy>
          <iyz>0</iyz>
          <izz>0.00158</izz>
        </inertia>
      </inertial>
      <!-- <collision name='RL_HIP_collision'>
        <pose>0 0 0 0 -0 0</pose>
        <geometry>
          <box>
            <size>0.1 0.08 0.1</size>
          </box>
        </geometry>
      </collision> -->
      <visual name='RL_HIP_visual'>
        <pose>0 0 0 0 -0 0</pose>
        <geometry>
          <mesh>
            <scale>1 1 1</scale>
            <uri>model://PONGBOT_W/meshes/RL_HIP.STL</uri>
          </mesh>
        </geometry>
        <material>
          <ambient>244 67 54 1</ambient>
          <diffuse>1 1 1 1</diffuse>
          <emissive>0 0 0 1</emissive>
          <specular>0 0 0 0</specular>
        </material>
      </visual>
      <!-- <visual name='RL_HIP_visual'>
        <pose>0 0 0 0 -0 0</pose>
        <geometry>
          <box>
            <size>0.1 0.08 0.1</size>
          </box>
        </geometry>
      </visual> -->
    </link>
    <joint name='RL_HP_JOINT' type='revolute'>
      <pose relative_to='RL_HIP'>0 0.105 0 0 -0 0</pose>
      <parent>RL_HIP</parent>
      <child>RL_THIGH</child>
      <axis>
        <xyz>0 1 0</xyz>
        <limit>
          <!-- <lower>-1e+16</lower>
          <upper>1e+16</upper> -->
          <lower>-0.9075</lower>
          <upper>3.0194</upper>
          <effort>150</effort>
          <velocity>8.2</velocity>
        </limit>
        <dynamics>
          <spring_reference>0</spring_reference>
          <spring_stiffness>0</spring_stiffness>
          <!-- <damping>0.25</damping>
          <friction>0.02</friction> -->
        </dynamics>
      </axis>
    </joint>
    <link name='RL_THIGH'>
      <pose relative_to='RL_HP_JOINT'>0 0 0 0 -0 0</pose>
      <inertial>
        <pose>-7e-05 -0.00772 -0.03599 0 -0 0</pose>
        <mass>3.32</mass>
        <inertia>
          <ixx>0.027</ixx>
          <ixy>-5e-05</ixy>
          <ixz>-3e-05</ixz>
          <iyy>0.02726</iyy>
          <iyz>-0.00086</iyz>
          <izz>0.00394</izz>
        </inertia>
      </inertial>
      <!-- <collision name='RL_THIGH_collision'>
        <pose>0 0 -0.15 0 -0 0</pose>
        <geometry>
          <box>
            <size>0.08 0.05 0.3</size>
          </box>
        </geometry>
      </collision> -->
      <visual name='RL_THIGH_visual'>
        <pose>0 0 0 0 -0 0</pose>
        <geometry>
          <mesh>
            <scale>1 1 1</scale>
            <uri>model://PONGBOT_W/meshes/RL_THIGH.STL</uri>
          </mesh>
        </geometry>
        <material>
          <ambient>244 67 54 1</ambient>
          <diffuse>1 1 1 1</diffuse>
          <emissive>0 0 0 1</emissive>
          <specular>0 0 0 0</specular>
        </material>
      </visual>
    </link>
    <joint name='RL_KN_JOINT' type='revolute'>
      <pose relative_to='RL_THIGH'>0 0 -0.305 0 -0 0</pose>
      <parent>RL_THIGH</parent>
      <child>RL_CALF</child>
      <axis>
        <xyz>0 1 0</xyz>
        <limit>
          <!-- <lower>-1e+16</lower>
          <upper>1e+16</upper> -->
          <lower>-2.4958</lower>
          <upper>-0.6457</upper>
          <effort>268.5</effort>
          <velocity>4.82</velocity>
        </limit>
        <dynamics>
          <spring_reference>0</spring_reference>
          <spring_stiffness>0</spring_stiffness>
          <!-- <damping>0.25</damping>
          <friction>0.02</friction> -->
        </dynamics>
      </axis>
    </joint>
    <link name='RL_CALF'>
      <pose relative_to='RL_KN_JOINT'>0 0 0 0 -0 0</pose>
      <inertial>
        <pose>0.00554 -0.00354 -0.22683 0 -0 0</pose>
        <mass>1.4843</mass>
        <inertia>
          <ixx>0.02812</ixx>
          <ixy>4E-05</ixy>
          <ixz>-0.00038</ixz>
          <iyy>0.02856</iyy>
          <iyz>0.00133</iyz>
          <izz>0.00135</izz>
        </inertia>
      </inertial>
      <!-- <collision name='RL_CALF_collision'>
        <pose>0 0 0 0 -0 0</pose>
        <geometry>
          <mesh>
            <scale>1 1 1</scale>
            <uri>model://PONGBOT_W/meshes/RL_CALF.STL</uri>
          </mesh>
        </geometry>
      </collision> -->
      <!-- <collision name='RL_CALF_fixed_joint_lump__RL_WHEEL_collision_1'>
        <pose>0 0.0405 -0.3292 1.5708 -0 0</pose>
        <geometry>
          <cylinder>
            <length>0.04</length>
            <radius>0.108</radius>
          </cylinder>
        </geometry>
      </collision> -->
      <visual name='RL_CALF_visual'>
        <pose>0 0 0 0 -0 0</pose>
        <geometry>
          <mesh>
            <scale>1 1 1</scale>
            <uri>model://PONGBOT_W/meshes/RL_CALF.STL</uri>
          </mesh>
        </geometry>
        <material>
          <ambient>0 0 0 1</ambient>
          <diffuse>1 1 1 1</diffuse>
          <emissive>0 0 0 1</emissive>
          <specular>0 0 0 0</specular>
        </material>
      </visual>
      <!-- <visual name='RL_CALF_fixed_joint_lump__RL_WHEEL_visual_1'>
        <pose>0 0.0405 -0.3292 0 -0 0</pose>
        <geometry>
          <mesh>
            <scale>1 1 1</scale>
            <uri>model://PONGBOT_W/meshes/RL_WHEEL.STL</uri>
          </mesh>
        </geometry>
      </visual> -->
    </link>
    <joint name='RL_WHEEL_JOINT' type='fixed'>
      <pose relative_to='RL_CALF'>0 0.0405 -0.3292 0 -0 0</pose>
      <parent>RL_CALF</parent>
      <child>RL_WHEEL</child>
      <!-- <axis>
        <xyz>0 1 0</xyz>
        <limit>
          <lower>-1e+16</lower>
          <upper>1e+16</upper>
        </limit>
        <dynamics>
          <spring_reference>0</spring_reference>
          <spring_stiffness>0</spring_stiffness>
          <damping>0.25</damping>
          <friction>0.02</friction>
        </dynamics>
      </axis> -->
    </joint>
    <link name='RL_WHEEL'>
      <pose relative_to='RL_WHEEL_JOINT'>0 0 0 0 -0 0</pose>
      <inertial>
        <pose>0 -0.00076 0 0 -0 0</pose>
        <mass>1.1204</mass>
        <inertia>
          <ixx>0.00401</ixx>
          <ixy>0</ixy>
          <ixz>0</ixz>
          <iyy>0.00769</iyy>
          <iyz>0</iyz>
          <izz>0.00401</izz>
        </inertia>
      </inertial>
      <collision name='RL_WHEEL_collision'>
        <pose>0 0 0 1.5708 -0 0</pose>
        <geometry>
          <!--mesh>
            <scale>1 1 1</scale>
            <uri>model://PONGBOT_W/meshes/RL_WHEEL.STL</uri>
          </mesh-->
          <cylinder>
            <radius>0.108</radius>
            <length>0.04</length>  
          </cylinder>
        </geometry>
        <surface>
          <bounce>
            <restitution_coefficient> 0 </restitution_coefficient>
          </bounce>
          <friction>
            <ode>
              <!-- <mu>  100  </mu>
              <mu2> 10  </mu2> -->
              <mu>  1.5  </mu>
              <mu2> 1.5  </mu2>
              <slip1> 0.0  </slip1>
              <slip2> 0.0  </slip2>
            </ode>
          </friction>
          <contact>
            <ode>
      	      <!-- <kp>10000000</kp>
              <kd>10000</kd> -->
              <kp>12500000</kp>
              <kd>3125</kd>
              <!--<max_vel>0.1</max_vel>
              <min_depth>0.0001</min_depth> -->
            </ode>
          </contact>
        </surface>
      </collision>
      <visual name='RL_WHEEL_visual'>
        <pose>0 0 0 0 -0 0</pose>
        <geometry>
          <mesh>
            <scale>1 1 1</scale>
            <uri>model://PONGBOT_W/meshes/RL_WHEEL.STL</uri>
          </mesh>
        </geometry>
        <material>
          <ambient>0 0 0 1</ambient>
          <diffuse>1 1 1 1</diffuse>
          <emissive>0 0 0 1</emissive>
          <specular>0 0 0 0</specular>
        </material>
      </visual>
    </link>


    <joint name='RR_HR_JOINT' type='revolute'>
      <pose relative_to='BODY'>-0.31804 -0.1138 0 0 -0 0</pose>
      <parent>BODY</parent>
      <child>RR_HIP</child>
      <axis>
        <xyz>1 0 0</xyz>
        <limit>
          <!-- <lower>-1e+16</lower>
          <upper>1e+16</upper> -->
          <lower>-0.6283</lower>
          <upper>0.6283</upper>
          <effort>76.5</effort>
          <velocity>14.5</velocity>
        </limit>
        <dynamics>
          <spring_reference>0</spring_reference>
          <spring_stiffness>0</spring_stiffness>
          <!-- <damping>0.25</damping>
          <friction>0.02</friction> -->
        </dynamics>
      </axis>
    </joint>
    <link name='RR_HIP'>
      <pose relative_to='RR_HR_JOINT'>0 0 0 0 -0 0</pose>
      <inertial>
        <pose>-0.0028 0.00524 0.00109 0 -0 0</pose>
        <mass>1.5871</mass>
        <inertia>
          <ixx>0.00134</ixx>
          <ixy>1e-05</ixy>
          <ixz>-1e-05</ixz>
          <iyy>0.00194</iyy>
          <iyz>-1e-05</iyz>
          <izz>0.00158</izz>
        </inertia>
      </inertial>
      <!-- <collision name='RR_HIP_collision'>
        <pose>0 0 0 0 -0 0</pose>
        <geometry>
          <box>
            <size>0.1 0.08 0.1</size>
          </box>
        </geometry>
      </collision> -->
      <visual name='RR_HIP_visual'>
        <pose>0 0 0 0 -0 0</pose>
        <geometry>
          <mesh>
            <scale>1 1 1</scale>
            <uri>model://PONGBOT_W/meshes/RR_HIP.STL</uri>
          </mesh>
        </geometry>
        <material>
          <ambient>244 67 54 1</ambient>
          <diffuse>1 1 1 1</diffuse>
          <emissive>0 0 0 1</emissive>
          <specular>0 0 0 0</specular>
        </material>
      </visual>
      <!-- <visual name='RR_HIP_visual'>
        <pose>0 0 0 0 -0 0</pose>
        <geometry>
          <box>
            <size>0.1 0.08 0.1</size>
          </box>
        </geometry>
      </visual> -->
    </link>
    <joint name='RR_HP_JOINT' type='revolute'>
      <pose relative_to='RR_HIP'>0 -0.105 0 0 -0 0</pose>
      <parent>RR_HIP</parent>
      <child>RR_THIGH</child>
      <axis>
        <xyz>0 1 0</xyz>
        <limit>
          <!-- <lower>-1e+16</lower>
          <upper>1e+16</upper> -->
          <lower>-0.9075</lower>
          <upper>3.0194</upper>
          <effort>150</effort>
          <velocity>8.2</velocity>
        </limit>
        <dynamics>
          <spring_reference>0</spring_reference>
          <spring_stiffness>0</spring_stiffness>
          <!-- <damping>0.25</damping>
          <friction>0.02</friction> -->
        </dynamics>
      </axis>
    </joint>
    <link name='RR_THIGH'>
      <pose relative_to='RR_HP_JOINT'>0 0 0 0 -0 0</pose>
      <inertial>
        <pose>7e-05 0.00772 -0.03599 0 -0 0</pose>
        <mass>3.32</mass>
        <inertia>
          <ixx>0.027</ixx>
          <ixy>-5e-05</ixy>
          <ixz>3e-05</ixz>
          <iyy>0.02726</iyy>
          <iyz>0.00086</iyz>
          <izz>0.00394</izz>
        </inertia>
      </inertial>
      <!-- <collision name='RR_THIGH_collision'>
        <pose>0 0 -0.15 0 -0 0</pose>
        <geometry>
          <box>
            <size>0.08 0.05 0.3</size>
          </box>
        </geometry>
      </collision> -->
      <visual name='RR_THIGH_visual'>
        <pose>0 0 0 0 -0 0</pose>
        <geometry>
          <mesh>
            <scale>1 1 1</scale>
            <uri>model://PONGBOT_W/meshes/RR_THIGH.STL</uri>
          </mesh>
        </geometry>
        <material>
          <ambient>244 67 54 1</ambient>
          <diffuse>1 1 1 1</diffuse>
          <emissive>0 0 0 1</emissive>
          <specular>0 0 0 0</specular>
        </material> 
      </visual>
    </link>
    <joint name='RR_KN_JOINT' type='revolute'>
      <pose relative_to='RR_THIGH'>0 0 -0.305 0 -0 0</pose>
      <parent>RR_THIGH</parent>
      <child>RR_CALF</child>
      <axis>
        <xyz>0 1 0</xyz>
        <limit>
          <!-- <lower>-1e+16</lower>
          <upper>1e+16</upper> -->
          <lower>-2.4958</lower>
          <upper>-0.6457</upper>
          <effort>268.5</effort>
          <velocity>4.82</velocity>
        </limit>
        <dynamics>
          <spring_reference>0</spring_reference>
          <spring_stiffness>0</spring_stiffness>
          <!-- <damping>0.25</damping>
          <friction>0.02</friction> -->
        </dynamics>
      </axis>
    </joint>
    <link name='RR_CALF'>
      <pose relative_to='RR_KN_JOINT'>0 0 0 0 -0 0</pose>
     <inertial>
        <pose>0.00555 0.00354 -0.22683 0 -0 0</pose>
        <mass>1.4843</mass>
        <inertia>
          <ixx>0.02812</ixx>
          <ixy>-4E-05</ixy>
          <ixz>-0.00038</ixz>
          <iyy>0.02856</iyy>
          <iyz>-0.00133</iyz>
          <izz>0.00135</izz>
        </inertia>
      </inertial>
      <!-- <collision name='RR_CALF_collision'>
        <pose>0 0 0 0 -0 0</pose>
        <geometry>
          <mesh>
            <scale>1 1 1</scale>
            <uri>model://PONGBOT_W/meshes/RR_CALF.STL</uri>
          </mesh>
        </geometry>
      </collision> -->
      <!-- <collision name='RR_CALF_fixed_joint_lump__RR_WHEEL_collision_1'>
        <pose>0 -0.0405 -0.3292 1.5708 -0 0</pose>
        <geometry>
          <cylinder>
            <length>0.04</length>
            <radius>0.108</radius>
          </cylinder>
        </geometry>
      </collision> -->
      <visual name='RR_CALF_visual'>
        <pose>0 0 0 0 -0 0</pose>
        <geometry>
          <mesh>
            <scale>1 1 1</scale>
            <uri>model://PONGBOT_W/meshes/RR_CALF.STL</uri>
          </mesh>
        </geometry>
        <material>
          <ambient>0 0 0 1</ambient>
          <diffuse>1 1 1 1</diffuse>
          <emissive>0 0 0 1</emissive>
          <specular>0 0 0 0</specular>
        </material>
      </visual>
      <!-- <visual name='RR_CALF_fixed_joint_lump__RR_WHEEL_visual_1'>
        <pose>0 -0.0405 -0.3292 0 -0 0</pose>
        <geometry>
          <mesh>
            <scale>1 1 1</scale>
            <uri>model://PONGBOT_W/meshes/RR_WHEEL.STL</uri>
          </mesh>
        </geometry>
      </visual> -->
    </link>
    <joint name='RR_WHEEL_JOINT' type='fixed'>
      <pose relative_to='RR_CALF'>0 -0.0405 -0.3292 0 -0 0</pose>
      <parent>RR_CALF</parent>
      <child>RR_WHEEL</child>
      <!-- <axis>
        <xyz>0 1 0</xyz>
        <limit>
          <lower>-1e+16</lower>
          <upper>1e+16</upper>
        </limit>
        <dynamics>
          <spring_reference>0</spring_reference>
          <spring_stiffness>0</spring_stiffness>
          <damping>0.25</damping>
          <friction>0.02</friction>
        </dynamics>
      </axis> -->
    </joint>
    <link name='RR_WHEEL'>
      <pose relative_to='RR_WHEEL_JOINT'>0 0 0 0 -0 0</pose>
      <inertial>
        <pose>0 0.00076 0 0 -0 0</pose>
        <mass>1.1204</mass>
        <inertia>
          <ixx>0.00401</ixx>
          <ixy>0</ixy>
          <ixz>0</ixz>
          <iyy>0.00769</iyy>
          <iyz>0</iyz>
          <izz>0.00401</izz>
        </inertia>
      </inertial>
      <collision name='RR_WHEEL_collision'>
        <pose>0 0 0 1.5708 -0 0</pose>
        <geometry>
          <!--mesh>
            <scale>1 1 1</scale>
            <uri>model://PONGBOT_W/meshes/RR_WHEEL.STL</uri>
          </mesh-->
          <cylinder>
            <radius>0.108</radius>
            <length>0.04</length>  
          </cylinder>
        </geometry>
        <surface>
          <bounce>
            <restitution_coefficient> 0 </restitution_coefficient>
          </bounce>
          <friction>
            <ode>
              <!-- <mu>  100  </mu>
              <mu2> 10  </mu2> -->
              <mu>  1.5  </mu>
              <mu2> 1.5  </mu2>
              <slip1> 0.0  </slip1>
              <slip2> 0.0  </slip2>
            </ode>
          </friction>
          <contact>
            <ode>
      	      <!-- <kp>10000000</kp>
              <kd>10000</kd> -->
              <kp>12500000</kp>
              <kd>3125</kd>
              <!-- <max_vel>0.1</max_vel>
              <min_depth>0.0001</min_depth> -->
            </ode>
          </contact>
        </surface>
      </collision>
      <visual name='RR_WHEEL_visual'>
        <pose>0 0 0 0 -0 0</pose>
        <geometry>
          <mesh>
            <scale>1 1 1</scale>
            <uri>model://PONGBOT_W/meshes/RR_WHEEL.STL</uri>
          </mesh>
        </geometry>
        <material>
          <ambient>0 0 0 1</ambient>
          <diffuse>1 1 1 1</diffuse>
          <emissive>0 0 0 1</emissive>
          <specular>0 0 0 0</specular>
        </material>
      </visual>
    </link>
    <!-- <frame name='FL_WHEEL_JOINT' attached_to='FL_CALF'>
      <pose>0 0.0405 -0.3292 0 -0 0</pose>
    </frame>
    <frame name='FL_WHEEL' attached_to='FL_WHEEL_JOINT'/>
    <frame name='FR_WHEEL_JOINT' attached_to='FR_CALF'>
      <pose>0 -0.0405 -0.3292 0 -0 0</pose>
    </frame>
    <frame name='FR_WHEEL' attached_to='FR_WHEEL_JOINT'/>
    <frame name='RL_WHEEL_JOINT' attached_to='RL_CALF'>
      <pose>0 0.0405 -0.3292 0 -0 0</pose>
    </frame>
    <frame name='RL_WHEEL' attached_to='RL_WHEEL_JOINT'/>
    <frame name='RR_WHEEL_JOINT' attached_to='RR_CALF'>
      <pose>0 -0.0405 -0.3292 0 -0 0</pose>
    </frame>
    <frame name='RR_WHEEL' attached_to='RR_WHEEL_JOINT'/> -->
  </model>
</sdf>
