<?xml version="1.0" encoding="utf-8"?>
<!-- This URDF was automatically created by SolidWorks to URDF Exporter! Originally created by Stephen Brawner (brawner@gmail.com) 
     Commit Version: 1.6.0-4-g7f85cfe  Build Version: 1.6.7995.38578
     For more information, please see http://wiki.ros.org/sw_urdf_exporter -->
<robot
  name="pongbotW">
  <link
    name="BASE">
    <inertial>
      <origin
        xyz="-0.0105 -0.00051 0.00089"
        rpy="0 0 0" />
      <mass
        value="29.589" />
      <inertia
        ixx="0.23275"
        ixy="-0.00319"
        ixz="-0.00016"
        iyy="1.3481"
        iyz="-0.00019"
        izz="1.4819" />
    </inertial>
    <visual>
      <origin
        xyz="0 0 0"
        rpy="0 0 0" />
      <geometry>
        <box
          size="0.5 0.3 0.12" />
        <!-- <mesh
          filename="../meshes/BASE.STL" /> -->
      </geometry>
      <material
        name="">
        <color
          rgba="0.75294 0.75294 0.75294 1" />
      </material>
    </visual>
    <collision>
      <origin
        xyz="0 0 0"
        rpy="0 0 0" />
      <geometry>
      <box
        size="0.5 0.3 0.12" />
        <!-- <mesh
          filename="../meshes/BASE.STL" /> -->
      </geometry>
    </collision>
  </link>
  <link
    name="RL_HIP">
    <inertial>
      <origin
        xyz="-0.0029 -0.00524 -0.00073"
        rpy="0 0 0" />
      <mass
        value="1.5871" />
      <inertia
        ixx="0.00134"
        ixy="-1E-05"
        ixz="1E-05"
        iyy="0.00194"
        iyz="0"
        izz="0.00158" />
    </inertial>
    <visual>
      <origin
        xyz="0 0 0"
        rpy="0 0 0" />
      <geometry>
      <box
        size="0.1 0.08 0.1" />
        <!-- <mesh
          filename="../meshes/RL_HIP.STL" /> -->
      </geometry>
      <material
        name="">
        <color
          rgba="0.75294 0.75294 0.75294 1" />
      </material>
    </visual>
    <collision>
      <origin
        xyz="0 0 0"
        rpy="0 0 0" />
      <geometry>
      <box
        size="0.1 0.08 0.1" />
        <!-- <mesh
          filename="../meshes/RL_HIP.STL" /> -->
      </geometry>
    </collision>
  </link>
  <joint
    name="RL_HR_JOINT"
    type="revolute">
    <origin
      xyz="-0.31804 0.1138 0"
      rpy="0 0 0" />
    <parent
      link="BASE" />
    <child
      link="RL_HIP" />
    <axis
      xyz="1 0 0" />
    <limit effort="76.5" lower="-0.6283" upper="0.6283" velocity="14.5"/>
    <!-- <limit
      lower="-0.6283"
      upper="0.6283"
      effort=
      velocity=/> -->
  </joint>
  <link
    name="RL_THIGH">
    <inertial>
      <origin
        xyz="-7E-05 -0.00772 -0.03599"
        rpy="0 0 0" />
      <mass
        value="3.32" />
      <inertia
        ixx="0.027"
        ixy="-5E-05"
        ixz="-3E-05"
        iyy="0.02726"
        iyz="-0.00086"
        izz="0.00394" />
    </inertial>
    <visual>
      <origin
        xyz="0 0 0"
        rpy="0 0 0" />
      <geometry>
      <!-- <box
        size="0.08 0.05 0.3" /> -->
        <mesh
          filename="../meshes/RL_THIGH.STL" />
      </geometry>
      <material
        name="">
        <color
          rgba="0.75294 0.75294 0.75294 1" />
      </material>
    </visual>
    <collision>
      <origin
        xyz="0 0 -0.15"
        rpy="0 0 0" />
      <geometry>
      <box
        size="0.08 0.05 0.3" />
        <!-- <mesh
          filename="../meshes/RL_THIGH.STL" /> -->
      </geometry>
    </collision>
  </link>
  <joint
    name="RL_HP_JOINT"
    type="revolute">
    <origin
      xyz="0 0.105 0"
      rpy="0 0 0" />
    <parent
      link="RL_HIP" />
    <child
      link="RL_THIGH" />
    <axis
      xyz="0 1 0" />
    <limit effort="150" lower="-0.9075" upper="3.0194" velocity="8.2"/>
    <!-- <limit
      lower="0"
      upper="0"/> -->
  </joint>
  <link
    name="RL_CALF">
    <inertial>
      <origin
        xyz="0.00554 -0.00354 -0.22683"
        rpy="0 0 0" />
      <mass
        value="1.4843" />
      <inertia
        ixx="0.02812"
        ixy="4E-05"
        ixz="-0.00038"
        iyy="0.02856"
        iyz="0.00133"
        izz="0.00135" />
    </inertial>
    <visual>
      <origin
        xyz="0 0 0"
        rpy="0 0 0" />
      <geometry>
        <mesh
          filename="../meshes/RL_CALF.STL" />
      </geometry>
      <material
        name="">
        <color
          rgba="0.75294 0.75294 0.75294 1" />
      </material>
    </visual>
    <collision>
      <origin
        xyz="0 0 0"
        rpy="0 0 0" />
      <geometry>
        <mesh
          filename="../meshes/RL_CALF.STL" />
      </geometry>
    </collision>
  </link>
  <joint
    name="RL_KN_JOINT"
    type="revolute">
    <origin
      xyz="0 0 -0.305"
      rpy="0 0 0" />
    <parent
      link="RL_THIGH" />
    <child
      link="RL_CALF" />
    <axis
      xyz="0 1 0" />
    <limit effort="268.5" lower="-2.4958" upper="-0.6457" velocity="4.82"/>
    <!-- <limit
      lower="0"
      upper="0"/> -->
  </joint>
  <link
    name="RL_WHEEL">
    <inertial>
      <origin
        xyz="0 -0.00076 0"
        rpy="0 0 0" />
      <mass
        value="1.1204" />
      <inertia
        ixx="0.00401"
        ixy="0"
        ixz="0"
        iyy="0.00769"
        iyz="0"
        izz="0.00401" />
    </inertial>
    <visual>
      <!-- <origin
        xyz="0 0 0"
        rpy="1.5708 0 0" /> -->
      <origin
      xyz="0 0 0"
      rpy="0 0 0" />
      <geometry>
        <mesh
          filename="../meshes/RL_WHEEL.STL" />
          <!-- <cylinder
          radius="0.108"
          length="0.04" /> -->
      </geometry>
      <material
        name="">
        <color
          rgba="0.75294 0.75294 0.75294 1" />
      </material>
    </visual>
    <collision>
      <origin
        xyz="0 0 0"
        rpy="1.5708 0 0" />
        <!-- rpy="1.5708 0 0" /> -->
      <geometry>
        <!-- <mesh
          filename="../meshes/RL_WHEEL.STL" /> -->
          <!-- <cylinder  -->
          <!-- radius="0.108" -->
          <!-- length="0.04" /> -->
          <sphere radius="0.108" />
      </geometry>
    </collision>
  </link>
  <joint
    name="RL_WHEEL_JOINT"
    type="continuous">
  <!-- <joint
    name="RL_WHEEL_JOINT"
    type="fixed"> -->
    <origin
      xyz="0 0.0405 -0.3292"
      rpy="0 0 0" />
    <parent
      link="RL_CALF" />
    <child
      link="RL_WHEEL" />
    <axis
      xyz="0 1 0" />
    <limit effort="9" velocity="19"/>
    <!-- <axis
      xyz="0 0 0" /> -->
    <!-- <limit
      lower="0"
      upper="0"/> -->
  </joint>
  <link
    name="RR_HIP">
    <inertial>
      <origin
        xyz="-0.0028 0.00524 0.00109"
        rpy="0 0 0" />
      <mass
        value="1.5871" />
      <inertia
        ixx="0.00134"
        ixy="1E-05"
        ixz="-1E-05"
        iyy="0.00194"
        iyz="-1E-05"
        izz="0.00158" />
    </inertial>
    <visual>
      <origin
        xyz="0 0 0"
        rpy="0 0 0" />
      <geometry>
      <box
        size="0.1 0.08 0.1" />
        <!-- <mesh
          filename="../meshes/RR_HIP.STL" /> -->
      </geometry>
      <material
        name="">
        <color
          rgba="0.75294 0.75294 0.75294 1" />
      </material>
    </visual>
    <collision>
      <origin
        xyz="0 0 0"
        rpy="0 0 0" />
      <geometry>
      <box
        size="0.1 0.08 0.1" />
        <!-- <mesh
          filename="../meshes/RR_HIP.STL" /> -->
      </geometry>
    </collision>
  </link>
  <joint
    name="RR_HR_JOINT"
    type="revolute">
    <origin
      xyz="-0.31804 -0.1138 0"
      rpy="0 0 0" />
    <parent
      link="BASE" />
    <child
      link="RR_HIP" />
    <axis
      xyz="1 0 0" />
    <limit effort="76.5" lower="-0.6283" upper="0.6283" velocity="14.5"/>
    <!-- <limit
      lower="0"
      upper="0"/> -->
  </joint>
  <link
    name="RR_THIGH">
    <inertial>
      <origin
        xyz="7E-05 0.00772 -0.03599"
        rpy="0 0 0" />
      <mass
        value="3.32" />
      <inertia
        ixx="0.027"
        ixy="-5E-05"
        ixz="3E-05"
        iyy="0.02726"
        iyz="0.00086"
        izz="0.00394" />
    </inertial>
    <visual>
      <origin
        xyz="0 0 0"
        rpy="0 0 0" />
      <geometry>
      <!-- <box
        size="0.08 0.05 0.3" /> -->
        <mesh
          filename="../meshes/RR_THIGH.STL" />
      </geometry>
      <material
        name="">
        <color
          rgba="0.75294 0.75294 0.75294 1" />
      </material>
    </visual>
    <collision>
      <origin
        xyz="0 0 -0.15"
        rpy="0 0 0" />
      <geometry>
      <box
        size="0.08 0.05 0.3" />
        <!-- <mesh
          filename="../meshes/RR_THIGH.STL" /> -->
      </geometry>
    </collision>
  </link>
  <joint
    name="RR_HP_JOINT"
    type="revolute">
    <origin
      xyz="0 -0.105 0"
      rpy="0 0 0" />
    <parent
      link="RR_HIP" />
    <child
      link="RR_THIGH" />
    <axis
      xyz="0 1 0" />
    <limit effort="150" lower="-0.9075" upper="3.0194" velocity="8.2"/>
    <!-- <limit
      lower="0"
      upper="0"/> -->
  </joint>
  <link
    name="RR_CALF">
    <inertial>
      <origin
        xyz="0.00555 0.00354 -0.22683"
        rpy="0 0 0" />
      <mass
        value="1.4843" />
      <inertia
        ixx="0.02812"
        ixy="-4E-05"
        ixz="-0.00038"
        iyy="0.02856"
        iyz="-0.00133"
        izz="0.00135" />
    </inertial>
    <visual>
      <origin
        xyz="0 0 0"
        rpy="0 0 0" />
      <geometry>
        <mesh
          filename="../meshes/RR_CALF.STL" />
      </geometry>
      <material
        name="">
        <color
          rgba="0.75294 0.75294 0.75294 1" />
      </material>
    </visual>
    <collision>
      <origin
        xyz="0 0 0"
        rpy="0 0 0" />
      <geometry>
        <mesh
          filename="../meshes/RR_CALF.STL" />
      </geometry>
    </collision>
  </link>
  <joint
    name="RR_KN_JOINT"
    type="revolute">
    <origin
      xyz="0 0 -0.305"
      rpy="0 0 0" />
    <parent
      link="RR_THIGH" />
    <child
      link="RR_CALF" />
    <axis
      xyz="0 1 0" />
    <limit effort="268.5" lower="-2.4958" upper="-0.6457" velocity="4.82"/>
    <!-- <limit
      lower="0"
      upper="0"/> -->
  </joint>
  <link
    name="RR_WHEEL">
    <inertial>
      <origin
        xyz="0 0.00076 0"
        rpy="0 0 0" />
      <mass
        value="1.1204" />
      <inertia
        ixx="0.00401"
        ixy="0"
        ixz="0"
        iyy="0.00769"
        iyz="0"
        izz="0.00401" />
    </inertial>
    <visual>
      <!-- <origin
        xyz="0 0 0"
        rpy="1.5708 0 0" /> -->
      <origin
      xyz="0 0 0"
      rpy="0 0 0" />
      <geometry>
        <mesh
          filename="../meshes/RR_WHEEL.STL" />
           <!-- <cylinder
          radius="0.108"
          length="0.04" /> -->
      </geometry>
      <material
        name="">
        <color
          rgba="0.75294 0.75294 0.75294 1" />
      </material>
    </visual>
    <collision>
      <origin
        xyz="0 0 0"
        rpy="1.5708 0 0" />
        <!-- rpy="1.5708 0 0" /> -->
      <geometry>
        <!-- <mesh
          filename="../meshes/RR_WHEEL.STL" /> -->
        <!-- <cylinder -->
          <!-- radius="0.108" -->
          <!-- length="0.04" /> -->
        <sphere radius="0.108" />

      </geometry>
    </collision>
  </link>
  <joint
    name="RR_WHEEL_JOINT"
    type="continuous">
  <!-- <joint
    name="RR_WHEEL_JOINT"
    type="fixed"> -->
    <origin
      xyz="0 -0.0405 -0.3292"
      rpy="0 0 0" />
    <parent
      link="RR_CALF" />
    <child
      link="RR_WHEEL" />
    <axis
      xyz="0 1 0" />
    <limit effort="9" velocity="19"/>
    <!-- <axis
      xyz="0 0 0" /> -->
    <!-- <limit
      lower="0"
      upper="0"/> -->
  </joint>
  <link
    name="FL_HIP">
    <inertial>
      <origin
        xyz="0.00261 -0.00524 0.00014"
        rpy="0 0 0" />
      <mass
        value="1.5871" />
      <inertia
        ixx="0.00134"
        ixy="0"
        ixz="1E-05"
        iyy="0.00194"
        iyz="-2E-05"
        izz="0.00158" />
    </inertial>
    <visual>
      <origin
        xyz="0 0 0"
        rpy="0 0 0" />
      <geometry>
      <box
        size="0.1 0.08 0.1" />
        <!-- <mesh
          filename="../meshes/FL_HIP.STL" /> -->
      </geometry>
      <material
        name="">
        <color
          rgba="0.75294 0.75294 0.75294 1" />
      </material>
    </visual>
    <collision>
      <origin
        xyz="0 0 0"
        rpy="0 0 0" />
      <geometry>
      <box
        size="0.1 0.08 0.1" />
        <!-- <mesh
          filename="../meshes/FL_HIP.STL" /> -->
      </geometry>
    </collision>
  </link>
  <joint
    name="FL_HR_JOINT"
    type="revolute">
    <origin
      xyz="0.31804 0.1138 0"
      rpy="0 0 0" />
    <parent
      link="BASE" />
    <child
      link="FL_HIP" />
    <axis
      xyz="1 0 0" />
    <limit effort="76.5" lower="-0.6283" upper="0.6283" velocity="14.5"/>
    <!-- <limit
      lower="0"
      upper="0"/> -->
  </joint>
  <link
    name="FL_THIGH">
    <inertial>
      <origin
        xyz="-7E-05 -0.00772 -0.03599"
        rpy="0 0 0" />
      <mass
        value="3.32" />
      <inertia
        ixx="0.027"
        ixy="-5E-05"
        ixz="-3E-05"
        iyy="0.02726"
        iyz="-0.00086"
        izz="0.00394" />
    </inertial>
    <visual>
      <origin
        xyz="0 0 0"
        rpy="0 0 0" />
      <geometry>
      <!-- <box
        size="0.08 0.05 0.3" /> -->
        <mesh
          filename="../meshes/FL_THIGH.STL" />
      </geometry>
      <material
        name="">
        <color
          rgba="0.75294 0.75294 0.75294 1" />
      </material>
    </visual>
    <collision>
      <origin
        xyz="0 0 -0.15"
        rpy="0 0 0" />
      <geometry>
      <box
        size="0.08 0.05 0.3" />
        <!-- <mesh
          filename="../meshes/FL_THIGH.STL" /> -->
      </geometry>
    </collision>
  </link>
  <joint
    name="FL_HP_JOINT"
    type="revolute">
    <origin
      xyz="0 0.105 0"
      rpy="0 0 0" />
    <parent
      link="FL_HIP" />
    <child
      link="FL_THIGH" />
    <axis
      xyz="0 1 0" />
    <limit effort="150" lower="-0.9075" upper="3.0194" velocity="8.2"/>
    <!-- <limit
      lower="0"
      upper="0"/> -->
  </joint>
  <link
    name="FL_CALF">
    <inertial>
      <origin
        xyz="0.00554 -0.00354 -0.22683"
        rpy="0 0 0" />
      <mass
        value="1.4843" />
      <inertia
        ixx="0.02812"
        ixy="4E-05"
        ixz="-0.00038"
        iyy="0.02856"
        iyz="0.00133"
        izz="0.00135" />
    </inertial>
    <visual>
      <origin
        xyz="0 0 0"
        rpy="0 0 0" />
      <geometry>
        <mesh
          filename="../meshes/FL_CALF.STL" />
      </geometry>
      <material
        name="">
        <color
          rgba="0.75294 0.75294 0.75294 1" />
      </material>
    </visual>
    <collision>
      <origin
        xyz="0 0 0"
        rpy="0 0 0" />
      <geometry>
        <mesh
          filename="../meshes/FL_CALF.STL" />
      </geometry>
    </collision>
  </link>
  <joint
    name="FL_KN_JOINT"
    type="revolute">
    <origin
      xyz="0 0 -0.305"
      rpy="0 0 0" />
    <parent
      link="FL_THIGH" />
    <child
      link="FL_CALF" />
    <axis
      xyz="0 1 0" />
    <limit effort="268.5" lower="-2.4958" upper="-0.6457" velocity="4.82"/>
    <!-- <limit
      lower="0"
      upper="0"/> -->
  </joint>
  <link
    name="FL_WHEEL">
    <inertial>
      <origin
        xyz="0 -0.00076 0"
        rpy="0 0 0" />
      <mass
        value="1.1204" />
      <inertia
        ixx="0.00401"
        ixy="0"
        ixz="0"
        iyy="0.00769"
        iyz="0"
        izz="0.00401" />
    </inertial>
    <visual>
      <!-- <origin
        xyz="0 0 0"
        rpy="1.5708 0 0" /> -->
      <origin
      xyz="0 0 0"
      rpy="0 0 0" />
      <geometry>
        <mesh
          filename="../meshes/FL_WHEEL.STL" />
          <!-- <cylinder
          radius="0.108"
          length="0.04" /> -->
      </geometry>
      <material
        name="">
        <color
          rgba="0.75294 0.75294 0.75294 1" />
      </material>
    </visual>
    <collision>
      <origin
        xyz="0 0 0"
        rpy="1.5708 0 0" />
        <!-- rpy="1.5708 0 0" /> -->
      <geometry>
        <!-- <mesh
          filename="../meshes/FL_WHEEL.STL" /> -->
          <!-- <cylinder -->
            <!-- radius="0.108" -->
            <!-- length="0.04" /> -->
          <sphere radius="0.108" />
      </geometry>
    </collision>
  </link>
  <joint
    name="FL_WHEEL_JOINT"
    type="continuous">
  <!-- <joint
    name="FL_WHEEL_JOINT"
    type="continous"> -->
    <origin
      xyz="0 0.0405 -0.3292"
      rpy="0 0 0" />
    <parent
      link="FL_CALF" />
    <child
      link="FL_WHEEL" />
    <axis
      xyz="0 1 0" />
    <limit effort="9" velocity="19"/>
    <!-- <axis
      xyz="0 0 0" /> -->
    <!-- <limit
      lower="0"
      upper="0"/> -->
  </joint>
  <link
    name="FR_HIP">
    <inertial>
      <origin
        xyz="0.0027 0.00524 0.00022"
        rpy="0 0 0" />
      <mass
        value="1.5871" />
      <inertia
        ixx="0.00134"
        ixy="-1E-05"
        ixz="-1E-05"
        iyy="0.00194"
        iyz="-4E-05"
        izz="0.00158" />
    </inertial>
    <visual>
      <origin
        xyz="0 0 0"
        rpy="0 0 0" />
      <geometry>
      <box
        size="0.1 0.08 0.1" />
        <!-- <mesh
          filename="../meshes/FR_HIP.STL" /> -->
      </geometry>
      <material
        name="">
        <color
          rgba="0.75294 0.75294 0.75294 1" />
      </material>
    </visual>
    <collision>
      <origin
        xyz="0 0 0"
        rpy="0 0 0" />
      <geometry>
      <box
        size="0.1 0.08 0.1" />
        <!-- <mesh
          filename="../meshes/FR_HIP.STL" /> -->
      </geometry>
    </collision>
  </link>
  <joint
    name="FR_HR_JOINT"
    type="revolute">
    <origin
      xyz="0.31804 -0.1138 0"
      rpy="0 0 0" />
    <parent
      link="BASE" />
    <child
      link="FR_HIP" />
    <axis
      xyz="1 0 0" />
    <limit effort="76.5" lower="-0.6283" upper="0.6283" velocity="14.5"/>
    <!-- <limit
      lower="0"
      upper="0"/> -->
  </joint>
  <link
    name="FR_THIGH">
    <inertial>
      <origin
        xyz="7E-05 0.00772 -0.03599"
        rpy="0 0 0" />
      <mass
        value="3.32" />
      <inertia
        ixx="0.027"
        ixy="-5E-05"
        ixz="3E-05"
        iyy="0.02726"
        iyz="0.00086"
        izz="0.00394" />
    </inertial>
    <visual>
      <origin
        xyz="0 0 0"
        rpy="0 0 0" />
      <geometry>
      <!-- <box
        size="0.08 0.05 0.3" /> -->
        <mesh
          filename="../meshes/FR_THIGH.STL" />
      </geometry>
      <material
        name="">
        <color
          rgba="0.75294 0.75294 0.75294 1" />
      </material>
    </visual>
    <collision>
      <origin
        xyz="0 0 -0.15"
        rpy="0 0 0" />
      <geometry>
      <box
        size="0.08 0.05 0.3" />
        <!-- <mesh
          filename="../meshes/FR_THIGH.STL" /> -->
      </geometry>
    </collision>
  </link>
  <joint
    name="FR_HP_JOINT"
    type="revolute">
    <origin
      xyz="0 -0.105 0"
      rpy="0 0 0" />
    <parent
      link="FR_HIP" />
    <child
      link="FR_THIGH" />
    <axis
      xyz="0 1 0" />
    <limit effort="150" lower="-0.9075" upper="3.0194" velocity="8.2"/>
    <!-- <limit
      lower="0"
      upper="0"/> -->
  </joint>
  <link
    name="FR_CALF">
    <inertial>
      <origin
        xyz="0.00555 0.00354 -0.22683"
        rpy="0 0 0" />
      <mass
        value="1.4843" />
      <inertia
        ixx="0.02812"
        ixy="-4E-05"
        ixz="-0.00038"
        iyy="0.02856"
        iyz="-0.00133"
        izz="0.00135" />
    </inertial>
    <visual>
      <origin
        xyz="0 0 0"
        rpy="0 0 0" />
      <geometry>
        <mesh
          filename="../meshes/FR_CALF.STL" />
      </geometry>
      <material
        name="">
        <color
          rgba="0.75294 0.75294 0.75294 1" />
      </material>
    </visual>
    <collision>
      <origin
        xyz="0 0 0"
        rpy="0 0 0" />
      <geometry>
        <mesh
          filename="../meshes/FR_CALF.STL" />
      </geometry>
    </collision>
  </link>
  <joint
    name="FR_KN_JOINT"
    type="revolute">
    <origin
      xyz="0 0 -0.305"
      rpy="0 0 0" />
    <parent
      link="FR_THIGH" />
    <child
      link="FR_CALF" />
    <axis
      xyz="0 1 0" />
    <limit effort="268.5" lower="-2.4958" upper="-0.6457" velocity="4.82"/>
    <!-- <limit
      lower="0"
      upper="0"/> -->
  </joint>
  <link
    name="FR_WHEEL">
    <inertial>
      <origin
        xyz="0 0.00076 0"
        rpy="0 0 0" />
      <mass
        value="1.1204" />
      <inertia
        ixx="0.00401"
        ixy="0"
        ixz="0"
        iyy="0.00769"
        iyz="0"
        izz="0.00401" />
    </inertial>
    <visual>
      <!-- <origin
        xyz="0 0 0"
        rpy="1.5708 0 0" /> -->
      <origin
      xyz="0 0 0"
      rpy="0 0 0" />
      <geometry>
        <mesh
          filename="../meshes/FR_WHEEL.STL" />
          <!-- <cylinder
          radius="0.108"
          length="0.04" /> -->
      </geometry>
      <material
        name="">
        <color
          rgba="0.75294 0.75294 0.75294 1" />
      </material>
    </visual>
    <collision>
      <origin
        xyz="0 0 0"
        rpy="1.5708 0 0" />
        <!-- rpy="1.5708 0 0" /> -->
      <geometry>
        <!-- <mesh
          filename="../meshes/FR_WHEEL.STL" /> -->
        <!-- <cylinder -->
          <!-- radius="0.108" -->
          <!-- length="0.04" /> -->
        <sphere radius="0.108" />
      </geometry>
    </collision>
  </link>
  <!-- <joint
    name="FR_WHEEL_JOINT"
    type="fixed"> -->
  <joint
    name="FR_WHEEL_JOINT"
    type="continuous">
    <origin
      xyz="0 -0.0405 -0.3292"
      rpy="0 0 0" />
    <parent
      link="FR_CALF" />
    <child
      link="FR_WHEEL" />
    <axis
      xyz="0 1 0" />

    <limit effort="9" velocity="19"/>
    <!-- <axis
      xyz="0 0 0" /> -->
    <!-- <limit
      effort = 100
      velocity = 20 /> -->
    <!-- <limit
      lower="0"
      upper="0"/> -->
  </joint>
</robot>
