<?xml version='1.0' encoding='utf-8'?>
<mujoco model="pongbotW">
  <compiler angle="radian" />
  <asset>
    <mesh name="RL_CALF" content_type="model/stl" file="../meshes/RL_CALF.STL" />
    <mesh name="RR_CALF" content_type="model/stl" file="../meshes/RR_CALF.STL" />
    <mesh name="FL_CALF" content_type="model/stl" file="../meshes/FL_CALF.STL" />
    <mesh name="FR_CALF" content_type="model/stl" file="../meshes/FR_CALF.STL" />
  </asset>
  <worldbody>
    <body name="BASE">
      <inertial pos="-0.0105 -0.00051 0.00089" quat="-0.00151209 0.707061 0.000510208 0.707151" mass="29.589" diaginertia="1.4819 1.34811 0.232741" />
      <joint name="floating_base_joint" type="free" />
      <geom size="0.25 0.15 0.06" type="box" rgba="0.75294 0.75294 0.75294 1" />
      <body name="RL_HIP" pos="-0.31804 0.1138 0">
        <inertial pos="-0.0029 -0.00524 -0.00073" quat="0.485531 0.505891 0.514623 0.493454" mass="1.5871" diaginertia="0.00194017 0.00158042 0.00133942" />
        <joint name="RL_HR_JOINT" pos="0 0 0" axis="1 0 0" range="-0.6283 0.6283" actuatorfrcrange="-76.5 76.5" />
        <geom size="0.05 0.04 0.05" type="box" rgba="0.75294 0.75294 0.75294 1" />
        <body name="RL_THIGH" pos="0 0.105 0">
          <inertial pos="-7e-05 -0.00772 -0.03599" quat="0.647601 -0.0113969 0.0144697 0.761757" mass="3.32" diaginertia="0.0272996 0.0269921 0.00390828" />
          <joint name="RL_HP_JOINT" pos="0 0 0" axis="0 1 0" range="-0.9075 3.0194" actuatorfrcrange="-150 150" />
          <geom size="0.04 0.025 0.15" pos="0 0 -0.15" type="box" rgba="0.75294 0.75294 0.75294 1" />
          <body name="RL_CALF" pos="0 0 -0.305">
            <inertial pos="0.00554 -0.00354 -0.22683" quat="0.721733 0.0225079 -0.0117259 0.691706" mass="1.4843" diaginertia="0.0286258 0.0281245 0.00127972" />
            <joint name="RL_KN_JOINT" pos="0 0 0" axis="0 1 0" range="-2.4958 -0.6457" actuatorfrcrange="-268.5 268.5" />
            <geom type="mesh" rgba="0.75294 0.75294 0.75294 1" mesh="RL_CALF" />
            <body name="RL_WHEEL" pos="0 0.0405 -0.3292">
              <inertial pos="0 -0.00076 0" quat="0.707107 0 0 0.707107" mass="1.1204" diaginertia="0.00769 0.00401 0.00401" />
              <joint name="RL_WHEEL_JOINT" pos="0 0 0" axis="0 1 0" actuatorfrcrange="-9 9" />
              <geom size="0.108" quat="0.707105 0.707108 0 0" rgba="0.75294 0.75294 0.75294 1" />
            </body>
          </body>
        </body>
      </body>
      <body name="RR_HIP" pos="-0.31804 -0.1138 0">
        <inertial pos="-0.0028 0.00524 0.00109" quat="0.521262 0.486666 0.49267 0.498717" mass="1.5871" diaginertia="0.00194045 0.00158012 0.00133943" />
        <joint name="RR_HR_JOINT" pos="0 0 0" axis="1 0 0" range="-0.6283 0.6283" actuatorfrcrange="-76.5 76.5" />
        <geom size="0.05 0.04 0.05" type="box" rgba="0.75294 0.75294 0.75294 1" />
        <body name="RR_THIGH" pos="0 -0.105 0">
          <inertial pos="7e-05 0.00772 -0.03599" quat="0.647601 0.0113969 -0.0144697 0.761757" mass="3.32" diaginertia="0.0272996 0.0269921 0.00390828" />
          <joint name="RR_HP_JOINT" pos="0 0 0" axis="0 1 0" range="-0.9075 3.0194" actuatorfrcrange="-150 150" />
          <geom size="0.04 0.025 0.15" pos="0 0 -0.15" type="box" rgba="0.75294 0.75294 0.75294 1" />
          <body name="RR_CALF" pos="0 0 -0.305">
            <inertial pos="0.00555 0.00354 -0.22683" quat="0.691706 -0.0117259 0.0225079 0.721733" mass="1.4843" diaginertia="0.0286258 0.0281245 0.00127972" />
            <joint name="RR_KN_JOINT" pos="0 0 0" axis="0 1 0" range="-2.4958 -0.6457" actuatorfrcrange="-268.5 268.5" />
            <geom type="mesh" rgba="0.75294 0.75294 0.75294 1" mesh="RR_CALF" />
            <body name="RR_WHEEL" pos="0 -0.0405 -0.3292">
              <inertial pos="0 0.00076 0" quat="0.707107 0 0 0.707107" mass="1.1204" diaginertia="0.00769 0.00401 0.00401" />
              <joint name="RR_WHEEL_JOINT" pos="0 0 0" axis="0 1 0" actuatorfrcrange="-9 9" />
              <geom size="0.108" quat="0.707105 0.707108 0 0" rgba="0.75294 0.75294 0.75294 1" />
            </body>
          </body>
        </body>
      </body>
      <body name="FL_HIP" pos="0.31804 0.1138 0">
        <inertial pos="0.00261 -0.00524 0.00014" quat="0.50317 0.496346 0.523906 0.475376" mass="1.5871" diaginertia="0.00194111 0.00157931 0.00133958" />
        <joint name="FL_HR_JOINT" pos="0 0 0" axis="1 0 0" range="-0.6283 0.6283" actuatorfrcrange="-76.5 76.5" />
        <geom size="0.05 0.04 0.05" type="box" rgba="0.75294 0.75294 0.75294 1" />
        <body name="FL_THIGH" pos="0 0.105 0">
          <inertial pos="-7e-05 -0.00772 -0.03599" quat="0.647601 -0.0113969 0.0144697 0.761757" mass="3.32" diaginertia="0.0272996 0.0269921 0.00390828" />
          <joint name="FL_HP_JOINT" pos="0 0 0" axis="0 1 0" range="-0.9075 3.0194" actuatorfrcrange="-150 150" />
          <geom size="0.04 0.025 0.15" pos="0 0 -0.15" type="box" rgba="0.75294 0.75294 0.75294 1" />
          <body name="FL_CALF" pos="0 0 -0.305">
            <inertial pos="0.00554 -0.00354 -0.22683" quat="0.721733 0.0225079 -0.0117259 0.691706" mass="1.4843" diaginertia="0.0286258 0.0281245 0.00127972" />
            <joint name="FL_KN_JOINT" pos="0 0 0" axis="0 1 0" range="-2.4958 -0.6457" actuatorfrcrange="-268.5 268.5" />
            <geom type="mesh" rgba="0.75294 0.75294 0.75294 1" mesh="FL_CALF" />
            <body name="FL_WHEEL" pos="0 0.0405 -0.3292">
              <inertial pos="0 -0.00076 0" quat="0.707107 0 0 0.707107" mass="1.1204" diaginertia="0.00769 0.00401 0.00401" />
              <joint name="FL_WHEEL_JOINT" pos="0 0 0" axis="0 1 0" actuatorfrcrange="-9 9" />
              <geom size="0.108" quat="0.707105 0.707108 0 0" rgba="0.75294 0.75294 0.75294 1" />
            </body>
          </body>
        </body>
      </body>
      <body name="FR_HIP" pos="0.31804 -0.1138 0">
        <inertial pos="0.0027 0.00524 0.00022" quat="0.533387 0.456264 0.519077 0.487731" mass="1.5871" diaginertia="0.00194452 0.00157612 0.00133936" />
        <joint name="FR_HR_JOINT" pos="0 0 0" axis="1 0 0" range="-0.6283 0.6283" actuatorfrcrange="-76.5 76.5" />
        <geom size="0.05 0.04 0.05" type="box" rgba="0.75294 0.75294 0.75294 1" />
        <body name="FR_THIGH" pos="0 -0.105 0">
          <inertial pos="7e-05 0.00772 -0.03599" quat="0.647601 0.0113969 -0.0144697 0.761757" mass="3.32" diaginertia="0.0272996 0.0269921 0.00390828" />
          <joint name="FR_HP_JOINT" pos="0 0 0" axis="0 1 0" range="-0.9075 3.0194" actuatorfrcrange="-150 150" />
          <geom size="0.04 0.025 0.15" pos="0 0 -0.15" type="box" rgba="0.75294 0.75294 0.75294 1" />
          <body name="FR_CALF" pos="0 0 -0.305">
            <inertial pos="0.00555 0.00354 -0.22683" quat="0.691706 -0.0117259 0.0225079 0.721733" mass="1.4843" diaginertia="0.0286258 0.0281245 0.00127972" />
            <joint name="FR_KN_JOINT" pos="0 0 0" axis="0 1 0" range="-2.4958 -0.6457" actuatorfrcrange="-268.5 268.5" />
            <geom type="mesh" rgba="0.75294 0.75294 0.75294 1" mesh="FR_CALF" />
            <body name="FR_WHEEL" pos="0 -0.0405 -0.3292">
              <inertial pos="0 0.00076 0" quat="0.707107 0 0 0.707107" mass="1.1204" diaginertia="0.00769 0.00401 0.00401" />
              <joint name="FR_WHEEL_JOINT" pos="0 0 0" axis="0 1 0" actuatorfrcrange="-9 9" />
              <geom size="0.108" quat="0.707105 0.707108 0 0" rgba="0.75294 0.75294 0.75294 1" />
            </body>
          </body>
        </body>
      </body>
    </body>
    <geom name="ground" type="plane" pos="0 0 0" size="100 100 0.1" contype="1" conaffinity="1" friction="1.0 0.005 0.0001" rgba="0.5 0.5 0.5 1" />
    <light name="main_light" pos="0 -3 4" dir="0 0 -1" diffuse="0.8 0.8 0.8" />
  </worldbody>
  <option timestep="0.00500000" gravity="0 0 -9.81" />
</mujoco>